Workbook

Sheet 01_Executive_Dashboard
A1: GLOBAL ENTERPRISE FINANCIAL MODEL & EXECUTIVE DASHBOARD
A3: ACTIVE SCENARIO SELECTOR: | C3: Base | D3: (Valid options: Base | Bull | Bear — dynamic model linkages drive all projections)
A5: FY27 PROJ REVENUE | C5: FY27 EBITDA | E5: NET MARGIN (FY27) | G5: ENTERPRISE VALUE (DCF) | I5: PROJECT IRR | J5: ENDING CASH BALANCE
A6: ='03_3_Statement_Model'!F9 | C6: ='03_3_Statement_Model'!F15 | E6: ='03_3_Statement_Model'!F20/'03_3_Statement_Model'!F9 | G6: ='04_Valuation_DCF'!C19 | I6: ='04_Valuation_DCF'!C23 | J6: ='03_3_Statement_Model'!F38
A9: WORKBOOK ARCHITECTURE & SECTION QUICK JUMP
A10: • 02_Assumptions_&_Scenarios: Macro assumptions, pricing/volume drivers, and scenario matrices | E10: • 04_Valuation_DCF: Discounted Cash Flow, WACC build, Terminal Value, Sensitivity Tables | I10: • 06_Budget_vs_Actual_BvA: 12-month departmental variance analysis with SUMIFS and alert flags
A11: • 03_3_Statement_Model: Integrated 5-Year Income Statement, Balance Sheet & Cash Flow Statement | E11: • 05_Debt_&_Depreciation: Term loan amortization schedule (PMT/IPMT/PPMT) & asset depreciation | I11: • 07_Advanced_Formula_Lab: Modern dynamic arrays: LET, LAMBDA, FILTER, UNIQUE, SORT, XLOOKUP
A13: 5-YEAR HIGH-LEVEL CONSOLIDATED FINANCIAL SUMMARY ($)
A14: Financial Metric ($) | B14: FY2023 (Act) | C14: FY2024 (Act) | D14: FY2025 (Proj) | E14: FY2026 (Proj) | F14: FY2027 (Proj) | G14: 5-Yr CAGR
A15: Gross Revenue | B15: ='03_3_Statement_Model'!B9 | C15: ='03_3_Statement_Model'!C9 | D15: ='03_3_Statement_Model'!D9 | E15: ='03_3_Statement_Model'!E9 | F15: ='03_3_Statement_Model'!F9 | G15: =((F15/B15)^(1/4))-1
A16: Cost of Goods Sold (COGS) | B16: ='03_3_Statement_Model'!B10 | C16: ='03_3_Statement_Model'!C10 | D16: ='03_3_Statement_Model'!D10 | E16: ='03_3_Statement_Model'!E10 | F16: ='03_3_Statement_Model'!F10 | G16: =((F16/B16)^(1/4))-1
A17: Gross Profit | B17: ='03_3_Statement_Model'!B11 | C17: ='03_3_Statement_Model'!C11 | D17: ='03_3_Statement_Model'!D11 | E17: ='03_3_Statement_Model'!E11 | F17: ='03_3_Statement_Model'!F11 | G17: =((F17/B17)^(1/4))-1
A18: EBITDA | B18: ='03_3_Statement_Model'!B15 | C18: ='03_3_Statement_Model'!C15 | D18: ='03_3_Statement_Model'!D15 | E18: ='03_3_Statement_Model'!E15 | F18: ='03_3_Statement_Model'!F15 | G18: =((F18/B18)^(1/4))-1
A19: Net Operating Profit After Tax (NOPAT) | B19: ='04_Valuation_DCF'!B9 | C19: ='04_Valuation_DCF'!C9 | D19: ='04_Valuation_DCF'!D9 | E19: ='04_Valuation_DCF'!E9 | F19: ='04_Valuation_DCF'!F9 | G19: =((F19/B19)^(1/4))-1
A20: Free Cash Flow (FCF) | B20: ='04_Valuation_DCF'!B14 | C20: ='04_Valuation_DCF'!C14 | D20: ='04_Valuation_DCF'!D14 | E20: ='04_Valuation_DCF'!E14 | F20: ='04_Valuation_DCF'!F14 | G20: =((F20/B20)^(1/4))-1
A21: Ending Cash Balance | B21: ='03_3_Statement_Model'!B38 | C21: ='03_3_Statement_Model'!C38 | D21: ='03_3_Statement_Model'!D38 | E21: ='03_3_Statement_Model'!E38 | F21: ='03_3_Statement_Model'!F38 | G21: =((F21/B21)^(1/4))-1

Sheet 02_Assumptions_&_Scenarios
A1: FINANCIAL MODEL ASSUMPTIONS & SCENARIO ENGINE
A4: Active Scenario Selected: | C4: ='01_Executive_Dashboard'!C3
A5: Active Scenario ID (Index): | C5: =IF(C4="Base", 1, IF(C4="Bull", 2, IF(C4="Bear", 3, 1)))
A7: 1. SCENARIO MATRIX & OPERATIONAL GROWTH DRIVERS
A8: Scenario | B8: ID | C8: Annual Rev Growth % | D8: COGS % of Rev | E8: SG&A % of Rev | F8: Capex % of Rev | G8: Tax Rate %
A9: Base Case | B9: 1 | C9: 0.12 | D9: 0.42 | E9: 0.2 | F9: 0.05 | G9: 0.25
A10: Bull Case | B10: 2 | C10: 0.2 | D10: 0.38 | E10: 0.18 | F10: 0.06 | G10: 0.25
A11: Bear Case | B11: 3 | C11: 0.04 | D11: 0.48 | E11: 0.24 | F11: 0.04 | G11: 0.25
A13: ACTIVE DYNAMIC DRIVERS (Driven by Active Scenario Selector)
A14: Driver Name | B14: Active Value | C14: Formula / Method | D14: Description
A15: Revenue Growth Rate (YoY) | B15: =INDEX(C9:C11, $C$5) | C15: INDEX(C9:C11, $C$5) | D15: Dynamically looks up growth rate for active scenario
A16: COGS Ratio (% of Revenue) | B16: =INDEX(D9:D11, $C$5) | C16: INDEX(D9:D11, $C$5) | D16: Direct cost of goods/services ratio
A17: SG&A Ratio (% of Revenue) | B17: =INDEX(E9:E11, $C$5) | C17: INDEX(E9:E11, $C$5) | D17: Selling, General & Administrative expense intensity
A18: Capex Intensity (% of Revenue) | B18: =INDEX(F9:F11, $C$5) | C18: INDEX(F9:F11, $C$5) | D18: Capital expenditures allocation as % of revenue
A19: Corporate Tax Rate | B19: =INDEX(G9:G11, $C$5) | C19: INDEX(G9:G11, $C$5) | D19: Statutory corporate income tax rate
A22: 2. CAPITAL STRUCTURE & WACC VALUATION BENCHMARKS
A23: Risk-Free Rate (Rf) | B23: 0.042 | C23: 10-Year US Treasury Benchmark Yield
A24: Equity Risk Premium (ERP) | B24: 0.055 | C24: Expected historical market excess return
A25: Asset / Equity Beta (β) | B25: 1.15 | C25: Systematic equity risk / volatility factor
A26: Cost of Equity (Ke = Rf + β * ERP) | B26: =B23+(B25*B24) | C26: CAPM Capital Asset Pricing Model
A27: Pre-Tax Cost of Debt (Kd) | B27: 0.065 | C27: Weighted borrowing rate on senior term debt
A28: Effective Tax Rate (t) | B28: =B19 | C28: Corporate income tax shield
A29: After-Tax Cost of Debt [Kd * (1 - t)] | B29: =B27*(1-B28) | C29: Tax-shielded debt cost
A30: Target Debt Weight (Wd) | B30: 0.3 | C30: Capital structure % financed by debt
A31: Target Equity Weight (We) | B31: =1-B30 | C31: Capital structure % financed by equity
A32: WEIGHTED AVERAGE COST OF CAPITAL (WACC) | B32: =(B31*B26)+(B30*B29) | C32: Discount Rate: (We * Ke) + (Wd * Kd_after_tax)

Sheet 03_3_Statement_Model
A1: 5-YEAR INTEGRATED 3-STATEMENT FINANCIAL MODEL
A4: Line Item ($) | B4: FY2023 (Act) | C4: FY2024 (Act) | D4: FY2025 (Proj) | E4: FY2026 (Proj) | F4: FY2027 (Proj)
A5: A. CONSOLIDATED INCOME STATEMENT (P&L)
A9: Gross Revenue | B9: 10000000 | C9: 11500000 | D9: =B9*(1+'02_Assumptions_&_Scenarios'!$B$15) | E9: =C9*(1+'02_Assumptions_&_Scenarios'!$B$15) | F9: =D9*(1+'02_Assumptions_&_Scenarios'!$B$15)
A10: Cost of Goods Sold (COGS) | B10: 4300000 | C10: 4830000 | D10: =D9*'02_Assumptions_&_Scenarios'!$B$16 | E10: =E9*'02_Assumptions_&_Scenarios'!$B$16 | F10: =F9*'02_Assumptions_&_Scenarios'!$B$16
A11: Gross Profit | B11: =B9-B10 | C11: =C9-C10 | D11: =D9-D10 | E11: =E9-E10 | F11: =F9-F10
A12: Selling, General & Admin (SG&A) | B12: 2100000 | C12: 2350000 | D12: =D9*'02_Assumptions_&_Scenarios'!$B$17 | E12: =E9*'02_Assumptions_&_Scenarios'!$B$17 | F12: =F9*'02_Assumptions_&_Scenarios'!$B$17
A13: Research & Development (R&D) | B13: 800000 | C13: 920000 | D13: =D9*0.075 | E13: =E9*0.075 | F13: =F9*0.075
A14: Other Operating Expenses | B14: 300000 | C14: 350000 | D14: =D9*0.025 | E14: =E9*0.025 | F14: =F9*0.025
A15: EBITDA | B15: =B11-(B12+B13+B14) | C15: =C11-(C12+C13+C14) | D15: =D11-(D12+D13+D14) | E15: =E11-(E12+E13+E14) | F15: =F11-(F12+F13+F14)
A16: Depreciation & Amortization (D&A) | B16: 600000 | C16: 680000 | D16: ='05_Debt_&_Depreciation'!B35 | E16: ='05_Debt_&_Depreciation'!C35 | F16: ='05_Debt_&_Depreciation'!D35
A17: Operating Income (EBIT) | B17: =B15-B16 | C17: =C15-C16 | D17: =D15-D16 | E17: =E15-E16 | F17: =F15-F16
A18: Interest Expense | B18: 180000 | C18: 165000 | D18: ='05_Debt_&_Depreciation'!B20 | E18: ='05_Debt_&_Depreciation'!C20 | F18: ='05_Debt_&_Depreciation'!D20
A19: Earnings Before Taxes (EBT) | B19: =B17-B18 | C19: =C17-C18 | D19: =D17-D18 | E19: =E17-E18 | F19: =F17-F18
A20: Income Tax Expense | B20: =B19*'02_Assumptions_&_Scenarios'!$B$19 | C20: =C19*'02_Assumptions_&_Scenarios'!$B$19 | D20: =D19*'02_Assumptions_&_Scenarios'!$B$19 | E20: =E19*'02_Assumptions_&_Scenarios'!$B$19 | F20: =F19*'02_Assumptions_&_Scenarios'!$B$19
A21: NET INCOME | B21: =B19-B20 | C21: =C19-C20 | D21: =D19-D20 | E21: =E19-E20 | F21: =F19-F20
A23: B. CONSOLIDATED BALANCE SHEET
A25: Cash & Cash Equivalents | B25: 2500000 | C25: 3100000 | D25: =B38 | E25: =C38 | F25: =D38
A26: Accounts Receivable (45 days DSO) | B26: =B9*(45/365) | C26: =C9*(45/365) | D26: =D9*(45/365) | E26: =E9*(45/365) | F26: =F9*(45/365)
A27: Inventories (35 days DIO) | B27: =B10*(35/365) | C27: =C10*(35/365) | D27: =D10*(35/365) | E27: =E10*(35/365) | F27: =F10*(35/365)
A28: Total Current Assets | B28: =SUM(B25:B27) | C28: =SUM(C25:C27) | D28: =SUM(D25:D27) | E28: =SUM(E25:E27) | F28: =SUM(F25:F27)
A29: Property, Plant & Equipment (Net PP&E) | B29: 4200000 | C29: 4600000 | D29: ='05_Debt_&_Depreciation'!B36 | E29: ='05_Debt_&_Depreciation'!C36 | F29: ='05_Debt_&_Depreciation'!D36
A30: TOTAL ASSETS | B30: =B28+B29 | C30: =C28+C29 | D30: =D28+D29 | E30: =E28+E29 | F30: =F28+F29
A31: Accounts Payable (40 days DPO) | B31: =B10*(40/365) | C31: =C10*(40/365) | D31: =D10*(40/365) | E31: =E10*(40/365) | F31: =F10*(40/365)
A32: Current Senior Debt | B32: 400000 | C32: 450000 | D32: ='05_Debt_&_Depreciation'!B21 | E32: ='05_Debt_&_Depreciation'!C21 | F32: ='05_Debt_&_Depreciation'!D21
A33: Total Current Liabilities | B33: =B31+B32 | C33: =C31+C32 | D33: =D31+D32 | E33: =E31+E32 | F33: =F31+F32
A34: Long-Term Debt | B34: 2600000 | C34: 2150000 | D34: ='05_Debt_&_Depreciation'!B22 | E34: ='05_Debt_&_Depreciation'!C22 | F34: ='05_Debt_&_Depreciation'!D22
A35: TOTAL LIABILITIES | B35: =B33+B34 | C35: =C33+C34 | D35: =D33+D34 | E35: =E33+E34 | F35: =F33+F34
A36: Common Equity & Paid-in Capital | B36: 2000000 | C36: 2000000 | D36: =B36 | E36: =C36 | F36: =D36
A37: Retained Earnings | B37: 3000000 | C37: 4200000 | D37: =C37+D21 | E37: =D37+E21 | F37: =E37+F21
A38: TOTAL SHAREHOLDER EQUITY | B38: =B36+B37 | C38: =C36+C37 | D38: =D36+D37 | E38: =E36+E37 | F38: =F36+F37
A39: TOTAL LIABILITIES & EQUITY | B39: =B35+B38 | C39: =C35+C38 | D39: =D35+D38 | E39: =E35+E38 | F39: =F35+F38
A40: BALANCE SHEET CHECK (Assets - Liab & Eq) | B40: =B30-B39 | C40: =C30-C39 | D40: =D30-D39 | E40: =E30-E39 | F40: =F30-F39
A42: C. CONSOLIDATED STATEMENT OF CASH FLOWS
A44: Net Income | B44: =B21 | C44: =C21 | D44: =D21 | E44: =E21 | F44: =F21
A45: (+) Depreciation & Amortization | B45: =B16 | C45: =C16 | D45: =D16 | E45: =E16 | F45: =F16
A46: (-) Change in Accounts Receivable | B46: 0 | C46: =(B26-C26) | D46: =(C26-D26) | E46: =(D26-E26) | F46: =(E26-F26)
A47: (-) Change in Inventory | B47: 0 | C47: =(B27-C27) | D47: =(C27-D27) | E47: =(D27-E27) | F47: =(E27-F27)
A48: (+) Change in Accounts Payable | B48: 0 | C48: =(C31-B31) | D48: =(D31-C31) | E48: =(E31-D31) | F48: =(F31-E31)
A49: CASH FLOW FROM OPERATIONS (CFO) | B49: =SUM(B44:B48) | C49: =SUM(C44:C48) | D49: =SUM(D44:D48) | E49: =SUM(E44:E48) | F49: =SUM(F44:F48)
...

Sheet 04_Valuation_DCF
A1: DISCOUNTED CASH FLOW (DCF) VALUATION & RETURNS ENGINE
A4: Valuation Element ($) | B4: FY2023 (Act) | C4: FY2024 (Act) | D4: FY2025 (Proj) | E4: FY2026 (Proj) | F4: FY2027 (Proj) | G4: Terminal Year
A5: Operating Income (EBIT) | B5: ='03_3_Statement_Model'!B17 | C5: ='03_3_Statement_Model'!C17 | D5: ='03_3_Statement_Model'!D17 | E5: ='03_3_Statement_Model'!E17 | F5: ='03_3_Statement_Model'!F17 | G5: =F5*(1+0.025)
A6: Effective Tax Rate | B6: ='02_Assumptions_&_Scenarios'!$B$19 | C6: ='02_Assumptions_&_Scenarios'!$B$19 | D6: ='02_Assumptions_&_Scenarios'!$B$19 | E6: ='02_Assumptions_&_Scenarios'!$B$19 | F6: ='02_Assumptions_&_Scenarios'!$B$19 | G6: =F6
A7: (-) Taxes on EBIT | B7: =B5*B6 | C7: =C5*C6 | D7: =D5*D6 | E7: =E5*E6 | F7: =F5*F6 | G7: =G5*G6
A8: NOPAT (Net Operating Profit After Tax) | B8: =B5-B7 | C8: =C5-C7 | D8: =D5-D7 | E8: =E5-E7 | F8: =F5-F7 | G8: =G5-G7
A9: (+) Depreciation & Amortization | B9: ='03_3_Statement_Model'!B16 | C9: ='03_3_Statement_Model'!C16 | D9: ='03_3_Statement_Model'!D16 | E9: ='03_3_Statement_Model'!E16 | F9: ='03_3_Statement_Model'!F16 | G9: =F9*(1+0.025)
A10: (-) Capital Expenditures (Capex) | B10: =-'03_3_Statement_Model'!B50 | C10: =-'03_3_Statement_Model'!C50 | D10: =-'03_3_Statement_Model'!D50 | E10: =-'03_3_Statement_Model'!E50 | F10: =-'03_3_Statement_Model'!F50 | G10: =F10*(1+0.025)
A11: (-) Change in Net Working Capital (ΔNWC) | B11: 50000 | C11: 75000 | D11: 85000 | E11: 95000 | F11: 110000 | G11: =F11*(1+0.025)
A12: UNLEVERED FREE CASH FLOW (UFCF) | B12: =B8+B9-B10-B11 | C12: =C8+C9-C10-C11 | D12: =D8+D9-D10-D11 | E12: =E8+E9-E10-E11 | F12: =F8+F9-F10-F11 | G12: =G8+G9-G10-G11
A13: Discount Period (Years) | B13: 0 | C13: 0 | D13: 1 | E13: 2 | F13: 3 | G13: 4
A14: Discount Factor [1 / (1 + WACC)^t] | B14: 1 | C14: 1 | D14: =1/(1+'02_Assumptions_&_Scenarios'!$B$32)^D13 | E14: =1/(1+'02_Assumptions_&_Scenarios'!$B$32)^E13 | F14: =1/(1+'02_Assumptions_&_Scenarios'!$B$32)^F13 | G14: -
A15: PRESENT VALUE OF CASH FLOWS (PV) | B15: 0 | C15: 0 | D15: =D12*D14 | E15: =E12*E14 | F15: =F12*F14 | G15: -
A17: VALUATION OUTPUT & INSTITUTIONAL METRICS | E17: VALUATION SENSITIVITY: ENTERPRISE VALUE ($M) VS WACC & GROWTH
A18: Cumulative PV of Explicit Forecast (FY25-FY27) | B18: =SUM(D15:F15) | C18: Sum of discounted 3-year UFCF | E18: WACC \ g | F18: 1.5% | G18: 2.0% | H18: 2.5% | I18: 3.0%
A19: Terminal Value (Gordon Growth g=2.5%) | B19: =(G12*('02_Assumptions_&_Scenarios'!$B$32-0.025)) | C19: TV = UFCF_t+1 / (WACC - g) | E19: 0.075 | F19: =($B$18 + ($G$12 / (0.075 - 0.015)) * (1 / (1 + 0.075)^3)) / 1000000 | G19: =($B$18 + ($G$12 / (0.075 - 0.02)) * (1 / (1 + 0.075)^3)) / 1000000 | H19: =($B$18 + ($G$12 / (0.075 - 0.025)) * (1 / (1 + 0.075)^3)) / 1000000 | I19: =($B$18 + ($G$12 / (0.075 - 0.03)) * (1 / (1 + 0.075)^3)) / 1000000
A20: PV of Terminal Value | B20: =B19*(1/(1+'02_Assumptions_&_Scenarios'!$B$32)^3) | C20: Discounted back 3 years to present | E20: 0.085 | F20: =($B$18 + ($G$12 / (0.085 - 0.015)) * (1 / (1 + 0.085)^3)) / 1000000 | G20: =($B$18 + ($G$12 / (0.085 - 0.02)) * (1 / (1 + 0.085)^3)) / 1000000 | H20: =($B$18 + ($G$12 / (0.085 - 0.025)) * (1 / (1 + 0.085)^3)) / 1000000 | I20: =($B$18 + ($G$12 / (0.085 - 0.03)) * (1 / (1 + 0.085)^3)) / 1000000
A21: ENTERPRISE VALUE (EV) | B21: =B18+B20 | C21: Core operating value of business | E21: 0.095 | F21: =($B$18 + ($G$12 / (0.095 - 0.015)) * (1 / (1 + 0.095)^3)) / 1000000 | G21: =($B$18 + ($G$12 / (0.095 - 0.02)) * (1 / (1 + 0.095)^3)) / 1000000 | H21: =($B$18 + ($G$12 / (0.095 - 0.025)) * (1 / (1 + 0.095)^3)) / 1000000 | I21: =($B$18 + ($G$12 / (0.095 - 0.03)) * (1 / (1 + 0.095)^3)) / 1000000
A22: (-) Net Debt (Total Debt - Cash) | B22: ='03_3_Statement_Model'!F35-'03_3_Statement_Model'!F38 | C22: Market net indebtedness | E22: 0.105 | F22: =($B$18 + ($G$12 / (0.105 - 0.015)) * (1 / (1 + 0.105)^3)) / 1000000 | G22: =($B$18 + ($G$12 / (0.105 - 0.02)) * (1 / (1 + 0.105)^3)) / 1000000 | H22: =($B$18 + ($G$12 / (0.105 - 0.025)) * (1 / (1 + 0.105)^3)) / 1000000 | I22: =($B$18 + ($G$12 / (0.105 - 0.03)) * (1 / (1 + 0.105)^3)) / 1000000
A23: IMPLIED EQUITY VALUE | B23: =B21-B22 | C23: Value attributable to common shareholders | E23: 0.115 | F23: =($B$18 + ($G$12 / (0.115 - 0.015)) * (1 / (1 + 0.115)^3)) / 1000000 | G23: =($B$18 + ($G$12 / (0.115 - 0.02)) * (1 / (1 + 0.115)^3)) / 1000000 | H23: =($B$18 + ($G$12 / (0.115 - 0.025)) * (1 / (1 + 0.115)^3)) / 1000000 | I23: =($B$18 + ($G$12 / (0.115 - 0.03)) * (1 / (1 + 0.115)^3)) / 1000000
A24: XNPV (Formula Check - Exact Dates) | B24: =XNPV('02_Assumptions_&_Scenarios'!$B$32, D12:F12, DATE(2025,{12;12;12},{31;31;31})) | C24: Modern financial exact date discounting
A25: PROJECT IRR (Internal Rate of Return) | B25: =IRR(D12:F12) | C25: Unlevered internal return threshold

Sheet 05_Debt_&_Depreciation
A1: DEBT AMORTIZATION & MULTI-METHOD ASSET DEPRECIATION
A4: 1. SENIOR TERM LOAN AMORTIZATION SCHEDULE (PMT / IPMT / PPMT)
A5: Facility Principal Amount | B5: 3000000 | C5: Total senior credit facility borrowed
A6: Annual Interest Rate | B6: 0.065 | C6: Contractual coupon rate
A7: Tenor (Years) | B7: 5 | C7: Loan repayment duration
A8: Periods Per Year | B8: 12 | C8: Monthly amortization frequency
A9: Monthly Payment (PMT) | B9: =PMT(B6/B8, B7*B8, -B5) | C9: Contractual monthly debt service (P+I)
A10: Total 5-Year Interest Paid | B10: =(B9*B7*B8)-B5 | C10: Cumulative interest expense across life of loan
A12: Month | B12: Beg Balance ($) | C12: Total Payment ($) | D12: Principal (PPMT) ($) | E12: Interest (IPMT) ($) | F12: Ending Balance ($) | G12: Check
A13: 1 | B13: =$B$5 | C13: =$B$9 | D13: =PPMT($B$6/$B$8, A13, $B$7*$B$8, -$B$5) | E13: =IPMT($B$6/$B$8, A13, $B$7*$B$8, -$B$5) | F13: =B13-D13 | G13: =ROUND(C13-(D13+E13), 2)
A14: 2 | B14: =F13 | C14: =$B$9 | D14: =PPMT($B$6/$B$8, A14, $B$7*$B$8, -$B$5) | E14: =IPMT($B$6/$B$8, A14, $B$7*$B$8, -$B$5) | F14: =B14-D14 | G14: =ROUND(C14-(D14+E14), 2)
A15: 3 | B15: =F14 | C15: =$B$9 | D15: =PPMT($B$6/$B$8, A15, $B$7*$B$8, -$B$5) | E15: =IPMT($B$6/$B$8, A15, $B$7*$B$8, -$B$5) | F15: =B15-D15 | G15: =ROUND(C15-(D15+E15), 2)
A16: 4 | B16: =F15 | C16: =$B$9 | D16: =PPMT($B$6/$B$8, A16, $B$7*$B$8, -$B$5) | E16: =IPMT($B$6/$B$8, A16, $B$7*$B$8, -$B$5) | F16: =B16-D16 | G16: =ROUND(C16-(D16+E16), 2)
A17: 5 | B17: =F16 | C17: =$B$9 | D17: =PPMT($B$6/$B$8, A17, $B$7*$B$8, -$B$5) | E17: =IPMT($B$6/$B$8, A17, $B$7*$B$8, -$B$5) | F17: =B17-D17 | G17: =ROUND(C17-(D17+E17), 2)
A18: 6 | B18: =F17 | C18: =$B$9 | D18: =PPMT($B$6/$B$8, A18, $B$7*$B$8, -$B$5) | E18: =IPMT($B$6/$B$8, A18, $B$7*$B$8, -$B$5) | F18: =B18-D18 | G18: =ROUND(C18-(D18+E18), 2)
A19: 7 | B19: =F18 | C19: =$B$9 | D19: =PPMT($B$6/$B$8, A19, $B$7*$B$8, -$B$5) | E19: =IPMT($B$6/$B$8, A19, $B$7*$B$8, -$B$5) | F19: =B19-D19 | G19: =ROUND(C19-(D19+E19), 2)
A20: 8 | B20: =F19 | C20: =$B$9 | D20: =PPMT($B$6/$B$8, A20, $B$7*$B$8, -$B$5) | E20: =IPMT($B$6/$B$8, A20, $B$7*$B$8, -$B$5) | F20: =B20-D20 | G20: =ROUND(C20-(D20+E20), 2)
A21: 9 | B21: =F20 | C21: =$B$9 | D21: =PPMT($B$6/$B$8, A21, $B$7*$B$8, -$B$5) | E21: =IPMT($B$6/$B$8, A21, $B$7*$B$8, -$B$5) | F21: =B21-D21 | G21: =ROUND(C21-(D21+E21), 2)
A22: 10 | B22: =F21 | C22: =$B$9 | D22: =PPMT($B$6/$B$8, A22, $B$7*$B$8, -$B$5) | E22: =IPMT($B$6/$B$8, A22, $B$7*$B$8, -$B$5) | F22: =B22-D22 | G22: =ROUND(C22-(D22+E22), 2)
A23: 11 | B23: =F22 | C23: =$B$9 | D23: =PPMT($B$6/$B$8, A23, $B$7*$B$8, -$B$5) | E23: =IPMT($B$6/$B$8, A23, $B$7*$B$8, -$B$5) | F23: =B23-D23 | G23: =ROUND(C23-(D23+E23), 2)
A24: 12 | B24: =F23 | C24: =$B$9 | D24: =PPMT($B$6/$B$8, A24, $B$7*$B$8, -$B$5) | E24: =IPMT($B$6/$B$8, A24, $B$7*$B$8, -$B$5) | F24: =B24-D24 | G24: =ROUND(C24-(D24+E24), 2)
A27: 2. MULTI-METHOD DEPRECIATION SCHEDULE (SLN, DB, SYD COMPARISON)
A28: Asset Cost Basis ($): | B28: 5000000 | C28: Useful Life (Years): | D28: 5 | E28: Salvage Value ($): | F28: 500000
A30: Year | B30: Straight Line (SLN) | C30: Declining Balance (DB) | D30: Sum-of-Years' Digits (SYD) | E30: Cumulative SLN | F30: Net Book Value (SLN) | G30: Recommended
A31: Year 1 | B31: =SLN($B$28, $F$28, $D$28) | C31: =DB($B$28, $F$28, $D$28, 1) | D31: =SYD($B$28, $F$28, $D$28, 1) | E31: =B31 | F31: =$B$28-E31 | G31: GAAP / IFRS Base
A32: Year 2 | B32: =SLN($B$28, $F$28, $D$28) | C32: =DB($B$28, $F$28, $D$28, 2) | D32: =SYD($B$28, $F$28, $D$28, 2) | E32: =E31+B32 | F32: =$B$28-E32 | G32: GAAP / IFRS Base
A33: Year 3 | B33: =SLN($B$28, $F$28, $D$28) | C33: =DB($B$28, $F$28, $D$28, 3) | D33: =SYD($B$28, $F$28, $D$28, 3) | E33: =E32+B33 | F33: =$B$28-E33 | G33: GAAP / IFRS Base
A34: Year 4 | B34: =SLN($B$28, $F$28, $D$28) | C34: =DB($B$28, $F$28, $D$28, 4) | D34: =SYD($B$28, $F$28, $D$28, 4) | E34: =E33+B34 | F34: =$B$28-E34 | G34: GAAP / IFRS Base
A35: Year 5 | B35: =SLN($B$28, $F$28, $D$28) | C35: =DB($B$28, $F$28, $D$28, 5) | D35: =SYD($B$28, $F$28, $D$28, 5) | E35: =E34+B35 | F35: =$B$28-E35 | G35: GAAP / IFRS Base

Sheet 06_Budget_vs_Actual_BvA
A1: DEPARTMENTAL BUDGET VS ACTUAL (BvA) VARIANCE ENGINE
A4: Cost Center / Line Item | B4: Department | C4: Annual Budget ($) | D4: YTD Actuals ($) | E4: Variance ($) | F4: Variance (%) | G4: Status & Flag | H4: Audit Check
A5: Direct Labor & Engineering | B5: R&D | C5: 1200000 | D5: 1140000 | E5: =D5-C5 | F5: =E5/C5 | G5: =IF(E5>15000, "🚨 OVER BUDGET", IF(E5<-15000, "🟢 FAVORABLE", "✅ ON TARGET")) | H5: =IF(ISNUMBER(C5+D5), "OK", "ERR")
A6: Cloud Infrastructure & Servers | B6: R&D | C6: 450000 | D6: 485000 | E6: =D6-C6 | F6: =E6/C6 | G6: =IF(E6>15000, "🚨 OVER BUDGET", IF(E6<-15000, "🟢 FAVORABLE", "✅ ON TARGET")) | H6: =IF(ISNUMBER(C6+D6), "OK", "ERR")
A7: Software Licenses & Tools | B7: IT | C7: 220000 | D7: 210000 | E7: =D7-C7 | F7: =E7/C7 | G7: =IF(E7>15000, "🚨 OVER BUDGET", IF(E7<-15000, "🟢 FAVORABLE", "✅ ON TARGET")) | H7: =IF(ISNUMBER(C7+D7), "OK", "ERR")
A8: Sales Commission & Bonuses | B8: Sales | C8: 650000 | D8: 710000 | E8: =D8-C8 | F8: =E8/C8 | G8: =IF(E8>15000, "🚨 OVER BUDGET", IF(E8<-15000, "🟢 FAVORABLE", "✅ ON TARGET")) | H8: =IF(ISNUMBER(C8+D8), "OK", "ERR")
A9: Digital Marketing & Ads | B9: Marketing | C9: 500000 | D9: 480000 | E9: =D9-C9 | F9: =E9/C9 | G9: =IF(E9>15000, "🚨 OVER BUDGET", IF(E9<-15000, "🟢 FAVORABLE", "✅ ON TARGET")) | H9: =IF(ISNUMBER(C9+D9), "OK", "ERR")
A10: Executive & Management Salaries | B10: G&A | C10: 950000 | D10: 950000 | E10: =D10-C10 | F10: =E10/C10 | G10: =IF(E10>15000, "🚨 OVER BUDGET", IF(E10<-15000, "🟢 FAVORABLE", "✅ ON TARGET")) | H10: =IF(ISNUMBER(C10+D10), "OK", "ERR")
A11: Office Lease & Facilities | B11: G&A | C11: 360000 | D11: 360000 | E11: =D11-C11 | F11: =E11/C11 | G11: =IF(E11>15000, "🚨 OVER BUDGET", IF(E11<-15000, "🟢 FAVORABLE", "✅ ON TARGET")) | H11: =IF(ISNUMBER(C11+D11), "OK", "ERR")
A12: Legal, Audit & Compliance | B12: Legal | C12: 180000 | D12: 225000 | E12: =D12-C12 | F12: =E12/C12 | G12: =IF(E12>15000, "🚨 OVER BUDGET", IF(E12<-15000, "🟢 FAVORABLE", "✅ ON TARGET")) | H12: =IF(ISNUMBER(C12+D12), "OK", "ERR")
A13: Travel & Entertainment (T&E) | B13: Sales | C13: 140000 | D13: 165000 | E13: =D13-C13 | F13: =E13/C13 | G13: =IF(E13>15000, "🚨 OVER BUDGET", IF(E13<-15000, "🟢 FAVORABLE", "✅ ON TARGET")) | H13: =IF(ISNUMBER(C13+D13), "OK", "ERR")
A14: Customer Support & Success | B14: Operations | C14: 320000 | D14: 298000 | E14: =D14-C14 | F14: =E14/C14 | G14: =IF(E14>15000, "🚨 OVER BUDGET", IF(E14<-15000, "🟢 FAVORABLE", "✅ ON TARGET")) | H14: =IF(ISNUMBER(C14+D14), "OK", "ERR")
A15: Recruiting & Talent Acquisition | B15: HR | C15: 150000 | D15: 175000 | E15: =D15-C15 | F15: =E15/C15 | G15: =IF(E15>15000, "🚨 OVER BUDGET", IF(E15<-15000, "🟢 FAVORABLE", "✅ ON TARGET")) | H15: =IF(ISNUMBER(C15+D15), "OK", "ERR")
A16: Employee Health & Benefits | B16: HR | C16: 280000 | D16: 275000 | E16: =D16-C16 | F16: =E16/C16 | G16: =IF(E16>15000, "🚨 OVER BUDGET", IF(E16<-15000, "🟢 FAVORABLE", "✅ ON TARGET")) | H16: =IF(ISNUMBER(C16+D16), "OK", "ERR")
... A19: Contingency & Miscellaneous | B19: G&A | C19: 100000 | D19: 42000 | E19: =D19-C19 | F19: =E19/C19 | G19: =IF(E19>15000, "🚨 OVER BUDGET", IF(E19<-15000, "🟢 FAVORABLE", "✅ ON TARGET")) | H19: =IF(ISNUMBER(C19+D19), "OK", "ERR")
A20: CONSOLIDATED EXPENSES TOTAL | B20: All Depts | C20: =SUM(C5:C19) | D20: =SUM(D5:D19) | E20: =D20-C20 | F20: =E20/C20 | G20: =IF(E20>0, "🚨 NET DEFICIT", "🟢 NET SURPLUS") | H20: BALANCED
A23: DEPARTMENTAL SUMMARY ROLLUP VIA SUMIFS & AVERAGEIFS
A24: Department | B24: Line Items (COUNTIF) | C24: Total Budget ($) | D24: Total Actuals ($) | E24: Average Line Variance
A25: R&D | B25: =COUNTIF($B$5:$B$19, "R&D") | C25: =SUMIFS($C$5:$C$19, $B$5:$B$19, "R&D") | D25: =SUMIFS($D$5:$D$19, $B$5:$B$19, "R&D") | E25: =AVERAGEIFS($E$5:$E$19, $B$5:$B$19, "R&D")
A26: Sales | B26: =COUNTIF($B$5:$B$19, "Sales") | C26: =SUMIFS($C$5:$C$19, $B$5:$B$19, "Sales") | D26: =SUMIFS($D$5:$D$19, $B$5:$B$19, "Sales") | E26: =AVERAGEIFS($E$5:$E$19, $B$5:$B$19, "Sales")
A27: G&A | B27: =COUNTIF($B$5:$B$19, "G&A") | C27: =SUMIFS($C$5:$C$19, $B$5:$B$19, "G&A") | D27: =SUMIFS($D$5:$D$19, $B$5:$B$19, "G&A") | E27: =AVERAGEIFS($E$5:$E$19, $B$5:$B$19, "G&A")
A28: IT | B28: =COUNTIF($B$5:$B$19, "IT") | C28: =SUMIFS($C$5:$C$19, $B$5:$B$19, "IT") | D28: =SUMIFS($D$5:$D$19, $B$5:$B$19, "IT") | E28: =AVERAGEIFS($E$5:$E$19, $B$5:$B$19, "IT")
A29: HR | B29: =COUNTIF($B$5:$B$19, "HR") | C29: =SUMIFS($C$5:$C$19, $B$5:$B$19, "HR") | D29: =SUMIFS($D$5:$D$19, $B$5:$B$19, "HR") | E29: =AVERAGEIFS($E$5:$E$19, $B$5:$B$19, "HR")
A30: Operations | B30: =COUNTIF($B$5:$B$19, "Operations") | C30: =SUMIFS($C$5:$C$19, $B$5:$B$19, "Operations") | D30: =SUMIFS($D$5:$D$19, $B$5:$B$19, "Operations") | E30: =AVERAGEIFS($E$5:$E$19, $B$5:$B$19, "Operations")
A31: Legal | B31: =COUNTIF($B$5:$B$19, "Legal") | C31: =SUMIFS($C$5:$C$19, $B$5:$B$19, "Legal") | D31: =SUMIFS($D$5:$D$19, $B$5:$B$19, "Legal") | E31: =AVERAGEIFS($E$5:$E$19, $B$5:$B$19, "Legal")
A32: Finance | B32: =COUNTIF($B$5:$B$19, "Finance") | C32: =SUMIFS($C$5:$C$19, $B$5:$B$19, "Finance") | D32: =SUMIFS($D$5:$D$19, $B$5:$B$19, "Finance") | E32: =AVERAGEIFS($E$5:$E$19, $B$5:$B$19, "Finance")

Sheet 07_Advanced_Formula_Lab
A1: MODERN DYNAMIC ARRAYS & ADVANCED FORMULA SHOWCASE
A4: Technique / Formula | B4: Syntax Example | C4: Computed Result | D4: Compatibility | E4: Business Application & Advantage
A5: LET Variable Optimization | B5: =LET(rev, '03_3_Statement_Model'!F9, cogs, '03_3_Statement_Model'!F10, (rev-cogs)/rev) | C5: ='03_3_Statement_Model'!F11/'03_3_Statement_Model'!F9 | D5: Excel 365 / Sheets | E5: Eliminates redundant cell recalculation, accelerating large workbook speed by 4x
A6: XLOOKUP 2D Exact Match | B6: =XLOOKUP("Bull Case", '02_Assumptions_&_Scenarios'!A9:A11, '02_Assumptions_&_Scenarios'!C9:C11) | C6: ='02_Assumptions_&_Scenarios'!C10 | D6: Excel 2021+ / Sheets | E6: Replaces VLOOKUP with leftward lookups, default exact matching, and missing-key fallback
A7: INDEX / MATCH Classic Pair | B7: =INDEX('02_Assumptions_&_Scenarios'!C9:C11, MATCH("Bear Case", '02_Assumptions_&_Scenarios'!A9:A11, 0)) | C7: ='02_Assumptions_&_Scenarios'!C11 | D7: All Excel / All Sheets | E7: Universal institutional-grade matrix lookup compatible with all versions of spreadsheet engines
A8: SUMPRODUCT Weighted Metric | B8: =SUMPRODUCT('06_Budget_vs_Actual_BvA'!C5:C10, '06_Budget_vs_Actual_BvA'!F5:F10)/SUM('06_Budget_vs_Actual_BvA'!C5:C10) | C8: =SUMPRODUCT('06_Budget_vs_Actual_BvA'!C5:C10, '06_Budget_vs_Actual_BvA'!F5:F10)/SUM('06_Budget_vs_Actual_BvA'!C5:C10) | D8: All Excel / All Sheets | E8: Calculates dollar-weighted variance percentages across diverse departmental expense pools
A9: OFFSET Dynamic Rolling Range | B9: =AVERAGE(OFFSET('03_3_Statement_Model'!B9, 0, 0, 1, 3)) | C9: =AVERAGE('03_3_Statement_Model'!B9:D9) | D9: All Excel / All Sheets | E9: Dynamically averages moving multi-year fiscal performance without hardcoding column offsets
A10: INDIRECT Cross-Sheet Ref | B10: =INDIRECT("'01_Executive_Dashboard'!C3") | C10: ='01_Executive_Dashboard'!C3 | D10: All Excel / All Sheets | E10: Dynamically resolves target worksheet tabs based on dropdown strings or user selections
A11: FILTER High Variance Depts | B11: =FILTER('06_Budget_vs_Actual_BvA'!A5:E19, '06_Budget_vs_Actual_BvA'!E5:E19>10000) | C11: Dynamic Spill | D11: Excel 365 / Sheets | E11: Extracts all expense rows that breached target threshold automatically without macros or VBA
A12: UNIQUE Dimension Extractor | B12: =UNIQUE('06_Budget_vs_Actual_BvA'!B5:B19) | C12: Dynamic Spill | D12: Excel 365 / Sheets | E12: Auto-deduplicates organizational departments into clean dynamic validation lists
A13: SORT Ranked Performance | B13: =SORT('06_Budget_vs_Actual_BvA'!A5:E19, 5, -1) | C13: Dynamic Spill | D13: Excel 365 / Sheets | E13: Instant server-side array sorting by greatest variance dollar magnitude descending
A14: LAMBDA Custom Financial Math | B14: =LAMBDA(pv, r, n, pv*(1+r)^n)(1000, 0.08, 5) | C14: =1000*(1+0.08)^5 | D14: Excel 365 / Sheets | E14: Builds reusable, testable custom functions directly in formula bar without VBA modules

Sheet 08_Formula_Glossary_&_Guide
A1: EXCEL VS GOOGLE SHEETS COMPATIBILITY MATRIX & SHORTCUT CHEAT SHEET
A4: Formula / Feature Category | B4: Microsoft Excel (365 / Desktop) | C4: Google Sheets Equivalent | D4: Best Practice & Gotchas | E4: Status
A5: Exact Lookups | B5: =XLOOKUP(lookup, key_col, val_col, fallback) | C5: =XLOOKUP(lookup, key_col, val_col, fallback) | D5: Both support modern XLOOKUP natively. For legacy Excel 2013-2019, use INDEX(val_col, MATCH(key, key_col, 0)). | E5: 100% Native
A6: Dynamic Filtering | B6: =FILTER(array, condition, [if_empty]) | C6: =FILTER(range, condition1, [condition2]) | D6: Google Sheets requires multiple conditions passed as separate arguments or boolean multiplication *(col>x). | E6: 100% Native
A7: Dynamic Array Spills | B7: Automatic spill behavior across adjacent cells | C7: Automatic or wrap in =ARRAYFORMULA() for legacy cells | D7: In Google Sheets, wrap legacy single-cell operations like IF, CONCAT in ARRAYFORMULA() to spill. | E7: 100% Native
A8: Database / SQL Query | B8: Power Query (M Language) / Get & Transform | C8: =QUERY(A1:F100, "SELECT A, SUM(C) WHERE B='R&D' GROUP BY A") | D8: Google Sheets has the revolutionary QUERY() SQL function. In Excel, Power Query handles enterprise ETL. | E8: Cross-Platform
A9: Named Lambdas | B9: Defined via Name Manager -> New -> LAMBDA() | C9: Defined via Data -> Named functions | D9: Allows defining reusable functional macros without enabling VBA macros (.xlsm) or Apps Script. | E9: 100% Native
A10: External Data Sync | B10: Power Query Web Connector / OData Feed | C10: =IMPORTRANGE("sheet_url", "Tab!A1:Z") | D10: Google Sheets excels at cloud-to-cloud inter-workbook live linking with IMPORTRANGE. | E10: Native Cloud
A11: Discounted Cash Flow | B11: =NPV(rate, val1, val2...) + CF0 | C11: =NPV(rate, val1, val2...) + CF0 | D11: Remember that NPV assumes period 1 start! Always add initial investment (CF0) outside the NPV formula. | E11: Standardized
A12: Irregular Timing Returns | B12: =XIRR(values, dates) | C12: =XIRR(values, dates) | D12: Always format date columns as true Excel/Sheets dates rather than strings to avoid #VALUE! errors. | E12: Standardized
A13: Two-Way Table Lookup | B13: =INDEX(table, XMATCH(row_key, rows), XMATCH(col_key, cols)) | C13: =INDEX(table, MATCH(row_key, rows, 0), MATCH(col_key, cols, 0)) | D13: Rock-solid replacement for nested IF statements when querying 2D sensitivity matrices. | E13: Universal
A16: ESSENTIAL MODELING SHORTCUT CHEAT SHEET (WINDOWS VS MAC VS SHEETS)
A17: Action | B17: Excel (Windows PC) | C17: Excel (Mac OS) | D17: Google Sheets | E17: Productivity Impact
A18: Absolute Reference Toggle ($) | B18: F4 | C18: Command + T | D18: F4 | E18: Locks row/column coordinates ($A$1) instantly
A19: Fill Down / Fill Right | B19: Ctrl + D / Ctrl + R | C19: Cmd + D / Cmd + R | D19: Ctrl + D / Ctrl + R | E19: Massively speeds up formula horizontal/vertical cascading
A20: Paste Special Formats / Formulas | B20: Alt + E + S + T / F | C20: Cmd + Opt + V | D20: Ctrl + Alt + V | E20: Preserves exact border aesthetics and number formats
A21: Jump to Edge of Region | B21: Ctrl + Arrow Keys | C21: Cmd + Arrow Keys | D21: Ctrl + Arrow Keys | E21: Traverses 100k+ row financial ledgers in 1 click
A22: Select Entire Current Region | B22: Ctrl + Shift + 8 (Ctrl + *) | C22: Cmd + A | D22: Ctrl + A | E22: Selects bounded data matrix cleanly for pivot tables
A23: Format as Currency ($) | B23: Ctrl + Shift + 4 (Ctrl + $) | C23: Ctrl + Shift + $ | D23: Ctrl + Shift + 4 | E23: Applies standardized corporate currency format
A24: Format as Percentage (%) | B24: Ctrl + Shift + 5 (Ctrl + %) | C24: Ctrl + Shift + % | D24: Ctrl + Shift + 5 | E24: Converts decimal drivers to percentage displays
